#VRML_SIM R2022a utf8
WorldInfo {
}
Viewpoint {
  orientation 0.12987369235336774 0.04915340581235295 -0.9903114493590129 2.424373218424053
  position 0.1606883785799329 0.7977077481505459 0.39120469735064206
}
TexturedBackground {
}
TexturedBackgroundLight {
}
RectangleArena {
  translation 0.41 1.04 0
  floorSize 5 5
  floorAppearance Parquetry {
    type "dark strip"
  }
  wallHeight 0.2
}
Robot {
  translation -0.860023 0 0.06
  rotation 0 1 0 1.57
  children [
    DEF BODY_SHAPE Shape {
      appearance PBRAppearance {
        baseColor 0.666667 0 0.498039
        roughness 1
        metalness 0
      }
      geometry Capsule {
        height 0.2
        radius 0.05
      }
    }
    DEF ROLL_WHEEL HingeJoint {
      jointParameters HingeJointParameters {
        axis 0 0 1
      }
      device [
        DEF roll_motor RotationalMotor {
        }
        DEF r_sensor PositionSensor {
        }
      ]
      endPoint Solid {
        translation 0 0 0.3
        rotation -6.447254541048124e-09 -0.9999999999999999 6.447247967332037e-09 1.5707953071795862
        children [
          DEF roll Shape {
            appearance PBRAppearance {
              baseColor 0 1 0
              roughness 1
              metalness 0
            }
            geometry Cylinder {
              height 0.02
              radius 0.03
            }
          }
        ]
        boundingObject USE roll
        physics Physics {
        }
      }
    }
    DEF PITCH_WHEEL HingeJoint {
      jointParameters HingeJointParameters {
        axis 0 0 1
      }
      device [
        PositionSensor {
          name "p_sensor"
        }
        DEF pitch_motor RotationalMotor {
          name "pitch_motor"
        }
      ]
      endPoint Solid {
        children [
          DEF pitch Shape {
            appearance PBRAppearance {
              roughness 1
            }
            geometry Cylinder {
              height 0.03
              radius 0.06
              subdivision 30
            }
          }
        ]
        name "solid(2)"
        boundingObject USE pitch
        physics Physics {
        }
      }
    }
    DEF THIGHS Solid {
      translation -0.02 4.73704e-08 8.20112e-08
      rotation 0.5773509358560258 -0.577349935856137 0.577349935856137 2.09439
      children [
        DEF LEGS Shape {
          appearance PBRAppearance {
          }
          geometry DEF leg_shape Capsule {
            height 0.2
            radius 0.005
            subdivision 24
          }
        }
      ]
      name "thighs"
      boundingObject USE LEGS
      physics Physics {
      }
    }
    DEF TOES Solid {
      translation -0.008 0.11 -0.000492821
      rotation -0.35740612701840735 0.8628563066501258 -0.3574071270187627 -1.57
      children [
        DEF TOES Shape {
          appearance PBRAppearance {
          }
          geometry DEF toe_shape Capsule {
            height 0.03
            radius 0.005
            subdivision 24
          }
        }
      ]
      name "thighs(1)"
      boundingObject USE TOES
      physics Physics {
      }
    }
    DEF TOES Solid {
      translation -0.008 -0.11 -0.00038
      rotation 0.43792685970818224 0.8305777339207279 0.3440358897865722 -1.649255307179586
      children [
        DEF TOES Shape {
          appearance PBRAppearance {
          }
          geometry DEF toe_shape Capsule {
            height 0.03
            radius 0.005
            subdivision 24
          }
        }
      ]
      name "thighs(2)"
      boundingObject USE TOES
      physics Physics {
      }
    }
  ]
  name "chad"
  boundingObject USE BODY_SHAPE
  physics Physics {
  }
  controller "chad_controller"
}
